<?xml version="1.0"?>
<robot xmlns:xacro="http://www.ros.org/wiki/xacro" name="ddsm115_example">

  <!-- Two simple continuous joints -->
  <link  name="base_link"/>
  <link  name="joint1_link"/>
  <link  name="joint2_link"/>

  <joint name="joint1" type="continuous">
    <parent link="base_link"/>
    <child  link="joint1_link"/>
    <axis   xyz="0 0 1"/>
  </joint>

  <joint name="joint2" type="continuous">
    <parent link="joint1_link"/>
    <child  link="joint2_link"/>
    <axis   xyz="0 0 1"/>
  </joint>

<xacro:arg name="serialport" default="/dev/ttyUSB0"/>
<xacro:arg name="motor_ids"  default="1,2"/>

<ros2_control name="ddsm115_hw" type="system">
  <joint name="joint1"/>
  <joint name="joint2"/>

  <hardware>
    <plugin>ddsm115_hardware::DDSM115HardwareInterface</plugin>
    <!-- These two lines now actually end up in info.hardware_parameters -->
    <param name="serialport">/dev/ttyUSB0</param>
    <param name="motor_ids">1,2</param>
  </hardware>
</ros2_control>

</robot>
