<?xml version="1.0"?>
<robot xmlns:xacro="http://www.ros.org/wiki/xacro" name="ddsm115_example">

  <!-- Two simple continuous joints -->
  <link  name="base_link"/>
  <link  name="joint1_link"/>
  <link  name="joint2_link"/>

  <joint name="joint1" type="continuous">
    <parent link="base_link"/>
    <child  link="joint1_link"/>
    <origin xyz="0 0 0.1" rpy="0 0 0"/>
    <axis   xyz="0 0 1"/>
  </joint>

  <joint name="joint2" type="continuous">
    <parent link="joint1_link"/>
    <child  link="joint2_link"/>
    <origin xyz="0 0 0.25" rpy="0 1.57 0"/>
    <axis   xyz="0 0 1"/>
  </joint>


<ros2_control name="ddsm115_hw" type="system">
  <!-- <joint name="joint1"/>
  <joint name="joint2"/> -->
  
  <joint name="joint1">
      <param name="motor_id">1</param>
      <param name="mode">position</param>
  </joint>
  
  <joint name="joint2">
      <param name="motor_id">2</param>
      <param name="mode">velocity</param>
  </joint>


  <hardware>
    <plugin>ddsm115_hardware::DDSM115HardwareInterface</plugin>
    <param name="serialport">/dev/ttyUSB0</param>
    <!-- <param name="motor_ids">1,2</param>
    <param name="motor_modes">POSITION_LOOP,VELOCITY_LOOP</param> -->
  </hardware>
</ros2_control>

</robot>
